Workbook
Name SegmentaçãodeDados_A_receber: #N/A
Name SegmentaçãodeDados_Ano: #N/A
Name SegmentaçãodeDados_ano1: #N/A
Name SegmentaçãodeDados_Anos2: #N/A
Name SegmentaçãodeDados_Atrasado: #N/A
Name SegmentaçãodeDados_Descrição_Resumida: #N/A
Name SegmentaçãodeDados_Descrição_Resumida1: #N/A
Name SegmentaçãodeDados_FORNECEDOR: #N/A
Name SegmentaçãodeDados_SEMANA: #N/A

Sheet DashBoard Vendas

Sheet DBO Vendas
A1: ID | B1: N° do Pedido | C1: N° do Pedido na Loja Virtual | D1: Data | E1: ID contato | F1: Nome do contato | G1: Cpf/Cnpj | H1: Endereco | I1: Bairro | J1: Município | K1: Cep | L1: Estado | M1: E-mail | N1: Telefone | O1: Desconto pedido | P1: Frete | Q1: Observações | R1: Situação | S1: ID produto | T1: Descrição | U1: Quantidade | V1: Valor unitário | W1: Desconto item | X1: Preço de Custo | Y1: Preço Total | Z1: Código do contato | AA1: Código do produto | AB1: Frete proporcional | AC1: Desconto proporcional | AD1: Vendedor | AE1: Nº da NFe | AF1: Natureza da NFe | AG1: Situação da NFe | AH1: Última ocorrência | AI1: Outras despesas | AJ1: Outras despesas proporcional | AK1: Descrição Resumida | AL1: Peso
A2: 15284244295 | B2: 66 | D2: 44405 | E2: 15020006032 | F2: =VLOOKUP(RANDBETWEEN(1,20),'DBO Compras'!AA:AC,3,0) -> Comprador 01 | G2: 28.561.609/0001-59 | H2: Rodovia BR-277 Curitiba-Paranaguá, 3641 | I2: Cajuru | J2: Curitiba | K2: 82960015 | L2: PR | M2: teste@share-inc.com.br | N2: 41996838559 | O2: 0 | P2: 0 | R2: Atendido | S2: 15015085610 | T2: =VLOOKUP(RANDBETWEEN(1,17),'Auxiliar Vendas'!D:G,2,0) -> Produto 04 | U2: 10 | V2: 13.9 | W2: 0 | X2: 10.23 | Y2: 139 | Z2: 16 | AA2: PRFL.00.0001 | AB2: 0 | AC2: 0 | AH2: 44405.385 | AI2: 0 | AJ2: 0 | AK2: =VLOOKUP(T2,'Auxiliar Vendas'!E:F,2,FALSE) -> Produto 04 | AL2: =U2*VLOOKUP(T2,'Auxiliar Vendas'!E:G,3,FALSE) -> 6
A3: 15020046998 | B3: 1 | D3: 44407 | E3: 15020006032 | F3: =VLOOKUP(RANDBETWEEN(1,20),'DBO Compras'!AA:AC,3,0) -> Comprador 06 | G3: 28.561.609/0001-59 | H3: Rodovia BR-277 Curitiba-Paranaguá, 3641 | I3: Cajuru | J3: Curitiba | K3: 82960015 | L3: PR | M3: teste@share-inc.com.br | N3: 41996838559 | O3: 0 | P3: 0 | R3: Atendido | S3: 15015353721 | T3: =VLOOKUP(RANDBETWEEN(1,17),'Auxiliar Vendas'!D:G,2,0) -> Produto 17 | U3: 1000 | V3: 8.2 | W3: 0 | X3: 5.58 | Y3: 8200 | Z3: 16 | AA3: PRFL.00.0002 | AB3: 0 | AC3: 0 | AH3: 44407.585 | AI3: 0 | AJ3: 0 | AK3: =VLOOKUP(T3,'Auxiliar Vendas'!E:F,2,FALSE) -> Produto 17 | AL3: =U3*VLOOKUP(T3,'Auxiliar Vendas'!E:G,3,FALSE) -> 1420
A4: 15269414721 | B4: 23 | D4: 44408 | E4: 15058669306 | F4: =VLOOKUP(RANDBETWEEN(1,20),'DBO Compras'!AA:AC,3,0) -> Comprador 19 | G4: 03.387.992/0001-40 | H4: RUA ANTONIO GRECA, 91 | I4: AHU | J4: Curitiba | K4: 82200430 | L4: PR | M4: willian@walls.com.br | N4: 4191036801 | O4: 0 | P4: 0 | Q4: Ref. faturamento NFE saída 614. PAGO VM. | R4: Atendido | S4: 15016043939 | T4: =VLOOKUP(RANDBETWEEN(1,17),'Auxiliar Vendas'!D:G,2,0) -> Produto 01 | U4: 1000 | V4: 13.85 | W4: 0 | X4: 10.747 | Y4: 13850 | Z4: 17 | AA4: PRFL.00.0019 | AB4: 0 | AC4: 0 | AD4: AMANDA HUBBE | AH4: 44408.572 | AI4: 0 | AJ4: 0 | AK4: =VLOOKUP(T4,'Auxiliar Vendas'!E:F,2,FALSE) -> Produto 01 | AL4: =U4*VLOOKUP(T4,'Auxiliar Vendas'!E:G,3,FALSE) -> 400
A5: 15269487249 | B5: 24 | D5: 44408 | E5: 15020006032 | F5: =VLOOKUP(RANDBETWEEN(1,20),'DBO Compras'!AA:AC,3,0) -> Comprador 17 | G5: 28.561.609/0001-59 | H5: Rodovia BR-277 Curitiba-Paranaguá, 3641 | I5: Cajuru | J5: Curitiba | K5: 82960015 | L5: PR | M5: teste@share-inc.com.br | N5: 41996838559 | O5: 0 | P5: 0 | Q5: Ref. faturamento NFE saída 619. PAGO VM. | R5: Atendido | S5: 15015511068 | T5: =VLOOKUP(RANDBETWEEN(1,17),'Auxiliar Vendas'!D:G,2,0) -> Produto 15 | U5: 300 | V5: 16.2 | W5: 0 | X5: 10.23 | Y5: 4860 | Z5: 16 | AA5: PRFL.00.0005 | AB5: 0 | AC5: 0 | AH5: 44408.573 | AI5: 0 | AJ5: 0 | AK5: =VLOOKUP(T5,'Auxiliar Vendas'!E:F,2,FALSE) -> Produto 15 | AL5: =U5*VLOOKUP(T5,'Auxiliar Vendas'!E:G,3,FALSE) -> 426
A6: 15269550609 | B6: 25 | D6: 44408 | E6: 15179581888 | F6: =VLOOKUP(RANDBETWEEN(1,20),'DBO Compras'!AA:AC,3,0) -> Comprador 17 | G6: 44.114.658/0001-08 | H6: RUA JOAO RAPHAEL MACHADO, 496 | I6: Araucaria | J6: Curitiba | K6: 81350610 | L6: PR | M6: Marcio@destak.com.br | N6: 41996849234 | O6: 0 | P6: 0 | R6: Atendido | S6: 15015085610 | T6: =VLOOKUP(RANDBETWEEN(1,17),'Auxiliar Vendas'!D:G,2,0) -> Produto 15 | U6: 2340 | V6: 13.9 | W6: 0 | X6: 10.23 | Y6: 32526 | Z6: 41 | AA6: PRFL.00.0001 | AB6: 0 | AC6: 0 | AD6: HENRIQUE | AH6: 44408.385 | AI6: 0 | AJ6: 0 | AK6: =VLOOKUP(T6,'Auxiliar Vendas'!E:F,2,FALSE) -> Produto 15 | AL6: =U6*VLOOKUP(T6,'Auxiliar Vendas'!E:G,3,FALSE) -> 3322.8
A7: 15269550609 | B7: 25 | D7: 44408 | E7: 15179581888 | F7: =VLOOKUP(RANDBETWEEN(1,20),'DBO Compras'!AA:AC,3,0) -> Comprador 08 | G7: 44.114.658/0001-08 | H7: RUA JOAO RAPHAEL MACHADO, 496 | I7: Araucaria | J7: Curitiba | K7: 81350610 | L7: PR | M7: Marcio@destak.com.br | N7: 41996849234 | O7: 0 | P7: 0 | R7: Atendido | S7: 15015353721 | T7: =VLOOKUP(RANDBETWEEN(1,17),'Auxiliar Vendas'!D:G,2,0) -> Produto 11 | U7: 1452 | V7: 8.2 | W7: 0 | X7: 5.58 | Y7: 11906.4 | Z7: 41 | AA7: PRFL.00.0002 | AB7: 0 | AC7: 0 | AD7: HENRIQUE | AH7: 44408.385 | AI7: 0 | AJ7: 0 | AK7: =VLOOKUP(T7,'Auxiliar Vendas'!E:F,2,FALSE) -> Produto 11 | AL7: =U7*VLOOKUP(T7,'Auxiliar Vendas'!E:G,3,FALSE) -> 1597.2
A8: 15269550609 | B8: 25 | D8: 44408 | E8: 15179581888 | F8: =VLOOKUP(RANDBETWEEN(1,20),'DBO Compras'!AA:AC,3,0) -> Comprador 11 | G8: 44.114.658/0001-08 | H8: RUA JOAO RAPHAEL MACHADO, 496 | I8: Araucaria | J8: Curitiba | K8: 81350610 | L8: PR | M8: Marcio@destak.com.br | N8: 41996849234 | O8: 0 | P8: 0 | R8: Atendido | S8: 15015918644 | T8: =VLOOKUP(RANDBETWEEN(1,17),'Auxiliar Vendas'!D:G,2,0) -> Produto 04 | U8: 1000 | V8: 7.5 | W8: 0 | X8: 5.61 | Y8: 7500 | Z8: 41 | AA8: PRFL.00.0011 | AB8: 0 | AC8: 0 | AD8: HENRIQUE | AH8: 44408.385 | AI8: 0 | AJ8: 0 | AK8: =VLOOKUP(T8,'Auxiliar Vendas'!E:F,2,FALSE) -> Produto 04 | AL8: =U8*VLOOKUP(T8,'Auxiliar Vendas'!E:G,3,FALSE) -> 600
A9: 15280180552 | B9: 64 | D9: 44433 | E9: 15179608501 | F9: =VLOOKUP(RANDBETWEEN(1,20),'DBO Compras'!AA:AC,3,0) -> Comprador 04 | G9: 25.195.001/0001-60 | H9: RUA ITACIANO MARCONDES, 47 | I9: SANTA CANDIDA | J9: Curitiba | K9: 82720070 | L9: PR | M9: Delta@Delta.com.br | N9: 41992354686 | O9: 0 | P9: 0 | R9: Atendido | S9: 15016087271 | T9: =VLOOKUP(RANDBETWEEN(1,17),'Auxiliar Vendas'!D:G,2,0) -> Produto 01 | U9: 200 | V9: 18.2 | W9: 0 | X9: 14.4596 | Y9: 3640 | Z9: 42 | AA9: PRFL.00.0025 | AB9: 0 | AC9: 0 | AH9: 44433.49 | AI9: 0 | AJ9: 0 | AK9: =VLOOKUP(T9,'Auxiliar Vendas'!E:F,2,FALSE) -> Produto 01 | AL9: =U9*VLOOKUP(T9,'Auxiliar Vendas'!E:G,3,FALSE) -> 80
A10: 15280180552 | B10: 64 | D10: 44433 | E10: 15179608501 | F10: =VLOOKUP(RANDBETWEEN(1,20),'DBO Compras'!AA:AC,3,0) -> Comprador 14 | G10: 25.195.001/0001-60 | H10: RUA ITACIANO MARCONDES, 47 | I10: SANTA CANDIDA | J10: Curitiba | K10: 82720070 | L10: PR | M10: Delta@Delta.com.br | N10: 41992354686 | O10: 0 | P10: 0 | R10: Atendido | S10: 15016093155 | T10: =VLOOKUP(RANDBETWEEN(1,17),'Auxiliar Vendas'!D:G,2,0) -> Produto 07 | U10: 400 | V10: 16.17 | W10: 0 | X10: 14.4596 | Y10: 6468 | Z10: 42 | AA10: PRFL.00.0026 | AB10: 0 | AC10: 0 | AH10: 44433.49 | AI10: 0 | AJ10: 0 | AK10: =VLOOKUP(T10,'Auxiliar Vendas'!E:F,2,FALSE) -> Produto 07 | AL10: =U10*VLOOKUP(T10,'Auxiliar Vendas'!E:G,3,FALSE) -> 440
A11: 15280180552 | B11: 64 | D11: 44433 | E11: 15179608501 | F11: =VLOOKUP(RANDBETWEEN(1,20),'DBO Compras'!AA:AC,3,0) -> Comprador 18 | G11: 25.195.001/0001-60 | H11: RUA ITACIANO MARCONDES, 47 | I11: SANTA CANDIDA | J11: Curitiba | K11: 82720070 | L11: PR | M11: Delta@Delta.com.br | N11: 41992354686 | O11: 0 | P11: 0 | R11: Atendido | S11: 15015886084 | T11: =VLOOKUP(RANDBETWEEN(1,17),'Auxiliar Vendas'!D:G,2,0) -> Produto 15 | U11: 200 | V11: 18.13 | W11: 0 | X11: 15.996 | Y11: 3626 | Z11: 42 | AA11: PRFL.00.0009 | AB11: 0 | AC11: 0 | AH11: 44433.49 | AI11: 0 | AJ11: 0 | AK11: =VLOOKUP(T11,'Auxiliar Vendas'!E:F,2,FALSE) -> Produto 15 | AL11: =U11*VLOOKUP(T11,'Auxiliar Vendas'!E:G,3,FALSE) -> 284
A12: 15269564434 | B12: 26 | D12: 44438 | E12: 15058698393 | F12: =VLOOKUP(RANDBETWEEN(1,20),'DBO Compras'!AA:AC,3,0) -> Comprador 17 | G12: 21.267.641/0001-87 | H12: LOC RODOVIA DEP JOAO LEOPOLDO JA, 11432 | I12: CENTRO | J12: PINHAIS | K12: 83320382 | L12: PR | M12: Fabio@Install.com.br | N12: 41998972354 | O12: 0 | P12: 0 | R12: Atendido | S12: 15016043939 | T12: =VLOOKUP(RANDBETWEEN(1,17),'Auxiliar Vendas'!D:G,2,0) -> Produto 07 | U12: 500 | V12: 13.9 | W12: 0 | X12: 10.747 | Y12: 6950 | Z12: 18 | AA12: PRFL.00.0019 | AB12: 0 | AC12: 0 | AH12: 44438.573 | AI12: 0 | AJ12: 0 | AK12: =VLOOKUP(T12,'Auxiliar Vendas'!E:F,2,FALSE) -> Produto 07 | AL12: =U12*VLOOKUP(T12,'Auxiliar Vendas'!E:G,3,FALSE) -> 550
A13: 15269655769 | B13: 27 | D13: 44438 | E13: 15020006032 | F13: =VLOOKUP(RANDBETWEEN(1,20),'DBO Compras'!AA:AC,3,0) -> Comprador 19 | G13: 28.561.609/0001-59 | H13: Rodovia BR-277 Curitiba-Paranaguá, 3641 | I13: Cajuru | J13: Curitiba | K13: 82960015 | L13: PR | M13: teste@share-inc.com.br | N13: 41996838559 | O13: 0 | P13: 0 | R13: Atendido | S13: 15015511068 | T13: =VLOOKUP(RANDBETWEEN(1,17),'Auxiliar Vendas'!D:G,2,0) -> Produto 17 | U13: 500 | V13: 16.2 | W13: 0 | X13: 10.23 | Y13: 8100 | Z13: 16 | AA13: PRFL.00.0005 | AB13: 0 | AC13: 0 | AH13: 44438.574 | AI13: 0 | AJ13: 0 | AK13: =VLOOKUP(T13,'Auxiliar Vendas'!E:F,2,FALSE) -> Produto 17 | AL13: =U13*VLOOKUP(T13,'Auxiliar Vendas'!E:G,3,FALSE) -> 710
A14: 15269655769 | B14: 27 | D14: 44438 | E14: 15020006032 | F14: =VLOOKUP(RANDBETWEEN(1,20),'DBO Compras'!AA:AC,3,0) -> Comprador 05 | G14: 28.561.609/0001-59 | H14: Rodovia BR-277 Curitiba-Paranaguá, 3641 | I14: Cajuru | J14: Curitiba | K14: 82960015 | L14: PR | M14: teste@share-inc.com.br | N14: 41996838559 | O14: 0 | P14: 0 | R14: Atendido | S14: 15016043939 | T14: =VLOOKUP(RANDBETWEEN(1,17),'Auxiliar Vendas'!D:G,2,0) -> Produto 10 | U14: 500 | V14: 13.9 | W14: 0 | X14: 10.747 | Y14: 6950 | Z14: 16 | AA14: PRFL.00.0019 | AB14: 0 | AC14: 0 | AH14: 44438.574 | AI14: 0 | AJ14: 0 | AK14: =VLOOKUP(T14,'Auxiliar Vendas'!E:F,2,FALSE) -> Produto 10 | AL14: =U14*VLOOKUP(T14,'Auxiliar Vendas'!E:G,3,FALSE) -> 550
A15: 15269655769 | B15: 27 | D15: 44438 | E15: 15020006032 | F15: =VLOOKUP(RANDBETWEEN(1,20),'DBO Compras'!AA:AC,3,0) -> Comprador 02 | G15: 28.561.609/0001-59 | H15: Rodovia BR-277 Curitiba-Paranaguá, 3641 | I15: Cajuru | J15: Curitiba | K15: 82960015 | L15: PR | M15: teste@share-inc.com.br | N15: 41996838559 | O15: 0 | P15: 0 | R15: Atendido | S15: 15015918644 | T15: =VLOOKUP(RANDBETWEEN(1,17),'Auxiliar Vendas'!D:G,2,0) -> Produto 09 | U15: 2000 | V15: 8.2 | W15: 0 | X15: 5.61 | Y15: 16400 | Z15: 16 | AA15: PRFL.00.0011 | AB15: 0 | AC15: 0 | AH15: 44438.574 | AI15: 0 | AJ15: 0 | AK15: =VLOOKUP(T15,'Auxiliar Vendas'!E:F,2,FALSE) -> Produto 09 | AL15: =U15*VLOOKUP(T15,'Auxiliar Vendas'!E:G,3,FALSE) -> 2200
A16: 15269738581 | B16: 28 | D16: 44438 | E16: 15058719469 | F16: =VLOOKUP(RANDBETWEEN(1,20),'DBO Compras'!AA:AC,3,0) -> Comprador 10 | G16: 30.641.041/0001-28 | H16: RUA LEONARDO NOVICKI, 1554 | I16: CAJURU | J16: CURITIBA | K16: 82930548 | L16: PR | O16: 0 | P16: 0 | R16: Atendido | S16: 15016043939 | T16: =VLOOKUP(RANDBETWEEN(1,17),'Auxiliar Vendas'!D:G,2,0) -> Produto 04 | U16: 250 | V16: 13.9 | W16: 0 | X16: 10.747 | Y16: 3475 | Z16: 19 | AA16: PRFL.00.0019 | AB16: 0 | AC16: 0 | AH16: 44438.574 | AI16: 0 | AJ16: 0 | AK16: =VLOOKUP(T16,'Auxiliar Vendas'!E:F,2,FALSE) -> Produto 04 | AL16: =U16*VLOOKUP(T16,'Auxiliar Vendas'!E:G,3,FALSE) -> 150
A17: 15269738581 | B17: 28 | D17: 44438 | E17: 15058719469 | F17: =VLOOKUP(RANDBETWEEN(1,20),'DBO Compras'!AA:AC,3,0) -> Comprador 19 | G17: 30.641.041/0001-28 | H17: RUA LEONARDO NOVICKI, 1554 | I17: CAJURU | J17: CURITIBA | K17: 82930548 | L17: PR | O17: 0 | P17: 0 | R17: Atendido | S17: 15015918644 | T17: =VLOOKUP(RANDBETWEEN(1,17),'Auxiliar Vendas'!D:G,2,0) -> Produto 06 | U17: 250 | V17: 8.2 | W17: 0 | X17: 5.61 | Y17: 2050 | Z17: 19 | AA17: PRFL.00.0011 | AB17: 0 | AC17: 0 | AH17: 44438.574 | AI17: 0 | AJ17: 0 | AK17: =VLOOKUP(T17,'Auxiliar Vendas'!E:F,2,FALSE) -> Produto 06 | AL17: =U17*VLOOKUP(T17,'Auxiliar Vendas'!E:G,3,FALSE) -> 125
A18: 15269778195 | B18: 29 | D18: 44438 | E18: 15058741746 | F18: =VLOOKUP(RANDBETWEEN(1,20),'DBO Compras'!AA:AC,3,0) -> Comprador 01 | G18: 26.509.761/0001-67 | H18: AV JUSCELINO KUBITSCHEK DE OLIVEIRA, 2046, BRCAO A | I18: CIDADE INDUSTRIAL | J18: CURITIBA | K18: 81290000 | L18: PR | O18: 0 | P18: 0 | R18: Atendido | S18: 15015911944 | T18: =VLOOKUP(RANDBETWEEN(1,17),'Auxiliar Vendas'!D:G,2,0) -> Produto 01 | U18: 1000 | V18: 13.8 | W18: 0 | X18: 10.285 | Y18: 13800 | Z18: 20 | AA18: PRFL.00.0010 | AB18: 0 | AC18: 0 | AH18: 44438.574 | AI18: 0 | AJ18: 0 | AK18: =VLOOKUP(T18,'Auxiliar Vendas'!E:F,2,FALSE) -> Produto 01 | AL18: =U18*VLOOKUP(T18,'Auxiliar Vendas'!E:G,3,FALSE) -> 400
A19: 15269822282 | B19: 30 | D19: 44438 | E19: 15058669306 | F19: =VLOOKUP(RANDBETWEEN(1,20),'DBO Compras'!AA:AC,3,0) -> Comprador 18 | G19: 03.387.992/0001-40 | H19: RUA ANTONIO GRECA, 91 | I19: AHU | J19: Curitiba | K19: 82200430 | L19: PR | M19: willian@walls.com.br | N19: 4191036801 | O19: 0 | P19: 0 | R19: Atendido | S19: 15015911944 | T19: =VLOOKUP(RANDBETWEEN(1,17),'Auxiliar Vendas'!D:G,2,0) -> Produto 11 | U19: 300 | V19: 18.2 | W19: 0 | X19: 10.285 | Y19: 5460 | Z19: 17 | AA19: PRFL.00.0010 | AB19: 0 | AC19: 0 | AD19: AMANDA HUBBE | AH19: 44438.574 | AI19: 0 | AJ19: 0 | AK19: =VLOOKUP(T19,'Auxiliar Vendas'!E:F,2,FALSE) -> Produto 11 | AL19: =U19*VLOOKUP(T19,'Auxiliar Vendas'!E:G,3,FALSE) -> 330
A20: 15269822282 | B20: 30 | D20: 44438 | E20: 15058669306 | F20: =VLOOKUP(RANDBETWEEN(1,20),'DBO Compras'!AA:AC,3,0) -> Comprador 11 | G20: 03.387.992/0001-40 | H20: RUA ANTONIO GRECA, 91 | I20: AHU | J20: Curitiba | K20: 82200430 | L20: PR | M20: willian@walls.com.br | N20: 4191036801 | O20: 0 | P20: 0 | R20: Atendido | S20: 15016099089 | T20: =VLOOKUP(RANDBETWEEN(1,17),'Auxiliar Vendas'!D:G,2,0) -> Produto 16 | U20: 200 | V20: 21.3 | W20: 0 | X20: 16.8044 | Y20: 4260 | Z20: 17 | AA20: PRFL.00.0027 | AB20: 0 | AC20: 0 | AD20: AMANDA HUBBE | AH20: 44438.574 | AI20: 0 | AJ20: 0 | AK20: =VLOOKUP(T20,'Auxiliar Vendas'!E:F,2,FALSE) -> Produto 16 | AL20: =U20*VLOOKUP(T20,'Auxiliar Vendas'!E:G,3,FALSE) -> 254
A21: 15271227781 | B21: 41 | D21: 44438 | E21: 15179581888 | F21: =VLOOKUP(RANDBETWEEN(1,20),'DBO Compras'!AA:AC,3,0) -> Comprador 10 | G21: 44.114.658/0001-08 | H21: RUA JOAO RAPHAEL MACHADO, 496 | I21: Araucaria | J21: Curitiba | K21: 81350610 | L21: PR | M21: Marcio@destak.com.br | N21: 41996849234 | O21: 0 | P21: 0 | R21: Atendido | S21: 15015911944 | T21: =VLOOKUP(RANDBETWEEN(1,17),'Auxiliar Vendas'!D:G,2,0) -> Produto 02 | U21: 12040 | V21: 13.9 | W21: 0 | X21: 10.285 | Y21: 167356 | Z21: 41 | AA21: PRFL.00.0010 | AB21: 0 | AC21: 0 | AD21: HENRIQUE | AH21: 44438.383 | AI21: 0 | AJ21: 0 | AK21: =VLOOKUP(T21,'Auxiliar Vendas'!E:F,2,FALSE) -> Produto 02 | AL21: =U21*VLOOKUP(T21,'Auxiliar Vendas'!E:G,3,FALSE) -> 3250.8
A22: 15271227781 | B22: 41 | D22: 44438 | E22: 15179581888 | F22: =VLOOKUP(RANDBETWEEN(1,20),'DBO Compras'!AA:AC,3,0) -> Comprador 13 | G22: 44.114.658/0001-08 | H22: RUA JOAO RAPHAEL MACHADO, 496 | I22: Araucaria | J22: Curitiba | K22: 81350610 | L22: PR | M22: Marcio@destak.com.br | N22: 41996849234 | O22: 0 | P22: 0 | R22: Atendido | S22: 15016043939 | T22: =VLOOKUP(RANDBETWEEN(1,17),'Auxiliar Vendas'!D:G,2,0) -> Produto 04 | U22: 1000 | V22: 14 | W22: 0 | X22: 10.747 | Y22: 14000 | Z22: 41 | AA22: PRFL.00.0019 | AB22: 0 | AC22: 0 | AD22: HENRIQUE | AH22: 44438.383 | AI22: 0 | AJ22: 0 | AK22: =VLOOKUP(T22,'Auxiliar Vendas'!E:F,2,FALSE) -> Produto 04 | AL22: =U22*VLOOKUP(T22,'Auxiliar Vendas'!E:G,3,FALSE) -> 600
A23: 15271227781 | B23: 41 | D23: 44438 | E23: 15179581888 | F23: =VLOOKUP(RANDBETWEEN(1,20),'DBO Compras'!AA:AC,3,0) -> Comprador 06 | G23: 44.114.658/0001-08 | H23: RUA JOAO RAPHAEL MACHADO, 496 | I23: Araucaria | J23: Curitiba | K23: 81350610 | L23: PR | M23: Marcio@destak.com.br | N23: 41996849234 | O23: 0 | P23: 0 | R23: Atendido | S23: 15015085610 | T23: =VLOOKUP(RANDBETWEEN(1,17),'Auxiliar Vendas'!D:G,2,0) -> Produto 13 | U23: 100 | V23: 14.2 | W23: 0 | X23: 10.23 | Y23: 1420 | Z23: 41 | AA23: PRFL.00.0001 | AB23: 0 | AC23: 0 | AD23: HENRIQUE | AH23: 44438.383 | AI23: 0 | AJ23: 0 | AK23: =VLOOKUP(T23,'Auxiliar Vendas'!E:F,2,FALSE) -> Produto 13 | AL23: =U23*VLOOKUP(T23,'Auxiliar Vendas'!E:G,3,FALSE) -> 140
A24: 15271227781 | B24: 41 | D24: 44438 | E24: 15179581888 | F24: =VLOOKUP(RANDBETWEEN(1,20),'DBO Compras'!AA:AC,3,0) -> Comprador 19 | G24: 44.114.658/0001-08 | H24: RUA JOAO RAPHAEL MACHADO, 496 | I24: Araucaria | J24: Curitiba | K24: 81350610 | L24: PR | M24: Marcio@destak.com.br | N24: 41996849234 | O24: 0 | P24: 0 | R24: Atendido | S24: 15016043939 | T24: =VLOOKUP(RANDBETWEEN(1,17),'Auxiliar Vendas'!D:G,2,0) -> Produto 02 | U24: 200 | V24: 14.25 | W24: 0 | X24: 10.747 | Y24: 2850 | Z24: 41 | AA24: PRFL.00.0019 | AB24: 0 | AC24: 0 | AD24: HENRIQUE | AH24: 44438.383 | AI24: 0 | AJ24: 0 | AK24: =VLOOKUP(T24,'Auxiliar Vendas'!E:F,2,FALSE) -> Produto 02 | AL24: =U24*VLOOKUP(T24,'Auxiliar Vendas'!E:G,3,FALSE) -> 54
A25: 15271227781 | B25: 41 | D25: 44438 | E25: 15179581888 | F25: =VLOOKUP(RANDBETWEEN(1,20),'DBO Compras'!AA:AC,3,0) -> Comprador 07 | G25: 44.114.658/0001-08 | H25: RUA JOAO RAPHAEL MACHADO, 496 | I25: Araucaria | J25: Curitiba | K25: 81350610 | L25: PR | M25: Marcio@destak.com.br | N25: 41996849234 | O25: 0 | P25: 0 | R25: Atendido | S25: 15015085610 | T25: =VLOOKUP(RANDBETWEEN(1,17),'Auxiliar Vendas'!D:G,2,0) -> Produto 15 | U25: 20 | V25: 14.7 | W25: 0 | X25: 10.23 | Y25: 294 | Z25: 41 | AA25: PRFL.00.0001 | AB25: 0 | AC25: 0 | AD25: HENRIQUE | AH25: 44438.383 | AI25: 0 | AJ25: 0 | AK25: =VLOOKUP(T25,'Auxiliar Vendas'!E:F,2,FALSE) -> Produto 15 | AL25: =U25*VLOOKUP(T25,'Auxiliar Vendas'!E:G,3,FALSE) -> 28.4
A26: 15271227781 | B26: 41 | D26: 44438 | E26: 15179581888 | F26: =VLOOKUP(RANDBETWEEN(1,20),'DBO Compras'!AA:AC,3,0) -> Comprador 12 | G26: 44.114.658/0001-08 | H26: RUA JOAO RAPHAEL MACHADO, 496 | I26: Araucaria | J26: Curitiba | K26: 81350610 | L26: PR | M26: Marcio@destak.com.br | N26: 41996849234 | O26: 0 | P26: 0 | R26: Atendido | S26: 15015911944 | T26: =VLOOKUP(RANDBETWEEN(1,17),'Auxiliar Vendas'!D:G,2,0) -> Produto 17 | U26: 140 | V26: 14.9 | W26: 0 | X26: 10.285 | Y26: 2086 | Z26: 41 | AA26: PRFL.00.0010 | AB26: 0 | AC26: 0 | AD26: HENRIQUE | AH26: 44438.383 | AI26: 0 | AJ26: 0 | AK26: =VLOOKUP(T26,'Auxiliar Vendas'!E:F,2,FALSE) -> Produto 17 | AL26: =U26*VLOOKUP(T26,'Auxiliar Vendas'!E:G,3,FALSE) -> 198.8
A27: 15271227781 | B27: 41 | D27: 44438 | E27: 15179581888 | F27: =VLOOKUP(RANDBETWEEN(1,20),'DBO Compras'!AA:AC,3,0) -> Comprador 03 | G27: 44.114.658/0001-08 | H27: RUA JOAO RAPHAEL MACHADO, 496 | I27: Araucaria | J27: Curitiba | K27: 81350610 | L27: PR | M27: Marcio@destak.com.br | N27: 41996849234 | O27: 0 | P27: 0 | R27: Atendido | S27: 15015511068 | T27: =VLOOKUP(RANDBETWEEN(1,17),'Auxiliar Vendas'!D:G,2,0) -> Produto 09 | U27: 425 | V27: 13.9 | W27: 0 | X27: 10.23 | Y27: 5907.5 | Z27: 41 | AA27: PRFL.00.0005 | AB27: 0 | AC27: 0 | AD27: HENRIQUE | AH27: 44438.383 | AI27: 0 | AJ27: 0 | AK27: =VLOOKUP(T27,'Auxiliar Vendas'!E:F,2,FALSE) -> Produto 09 | AL27: =U27*VLOOKUP(T27,'Auxiliar Vendas'!E:G,3,FALSE) -> 467.5
A28: 15271227781 | B28: 41 | D28: 44438 | E28: 15179581888 | F28: =VLOOKUP(RANDBETWEEN(1,20),'DBO Compras'!AA:AC,3,0) -> Comprador 14 | G28: 44.114.658/0001-08 | H28: RUA JOAO RAPHAEL MACHADO, 496 | I28: Araucaria | J28: Curitiba | K28: 81350610 | L28: PR | M28: Marcio@destak.com.br | N28: 41996849234 | O28: 0 | P28: 0 | R28: Atendido | S28: 15015511068 | T28: =VLOOKUP(RANDBETWEEN(1,17),'Auxiliar Vendas'!D:G,2,0) -> Produto 05 | U28: 250 | V28: 16.7 | W28: 0 | X28: 10.23 | Y28: 4175 | Z28: 41 | AA28: PRFL.00.0005 | AB28: 0 | AC28: 0 | AD28: HENRIQUE | AH28: 44438.383 | AI28: 0 | AJ28: 0 | AK28: =VLOOKUP(T28,'Auxiliar Vendas'!E:F,2,FALSE) -> Produto 05 | AL28: =U28*VLOOKUP(T28,'Auxiliar Vendas'!E:G,3,FALSE) -> 150
A29: 15271227781 | B29: 41 | D29: 44438 | E29: 15179581888 | F29: =VLOOKUP(RANDBETWEEN(1,20),'DBO Compras'!AA:AC,3,0) -> Comprador 01 | G29: 44.114.658/0001-08 | H29: RUA JOAO RAPHAEL MACHADO, 496 | I29: Araucaria | J29: Curitiba | K29: 81350610 | L29: PR | M29: Marcio@destak.com.br | N29: 41996849234 | O29: 0 | P29: 0 | R29: Atendido | S29: 15015511068 | T29: =VLOOKUP(RANDBETWEEN(1,17),'Auxiliar Vendas'!D:G,2,0) -> Produto 03 | U29: 38 | V29: 17.7 | W29: 0 | X29: 10.23 | Y29: 672.6 | Z29: 41 | AA29: PRFL.00.0005 | AB29: 0 | AC29: 0 | AD29: HENRIQUE | AH29: 44438.383 | AI29: 0 | AJ29: 0 | AK29: =VLOOKUP(T29,'Auxiliar Vendas'!E:F,2,FALSE) -> Produto 03 | AL29: =U29*VLOOKUP(T29,'Auxiliar Vendas'!E:G,3,FALSE) -> 22.8
A30: 15271227781 | B30: 41 | D30: 44438 | E30: 15179581888 | F30: =VLOOKUP(RANDBETWEEN(1,20),'DBO Compras'!AA:AC,3,0) -> Comprador 13 | G30: 44.114.658/0001-08 | H30: RUA JOAO RAPHAEL MACHADO, 496 | I30: Araucaria | J30: Curitiba | K30: 81350610 | L30: PR | M30: Marcio@destak.com.br | N30: 41996849234 | O30: 0 | P30: 0 | R30: Atendido | S30: 15015918644 | T30: =VLOOKUP(RANDBETWEEN(1,17),'Auxiliar Vendas'!D:G,2,0) -> Produto 15 | U30: 6059 | V30: 8.2 | W30: 0 | X30: 5.61 | Y30: 49683.8 | Z30: 41 | AA30: PRFL.00.0011 | AB30: 0 | AC30: 0 | AD30: HENRIQUE | AH30: 44438.383 | AI30: 0 | AJ30: 0 | AK30: =VLOOKUP(T30,'Auxiliar Vendas'!E:F,2,FALSE) -> Produto 15 | AL30: =U30*VLOOKUP(T30,'Auxiliar Vendas'!E:G,3,FALSE) -> 8603.78
... A38: 15271227781 | B38: 41 | D38: 44438 | E38: 15179581888 | F38: =VLOOKUP(RANDBETWEEN(1,20),'DBO Compras'!AA:AC,3,0) -> Comprador 15 | G38: 44.114.658/0001-08 | H38: RUA JOAO RAPHAEL MACHADO, 496 | I38: Araucaria | J38: Curitiba | K38: 81350610 | L38: PR | M38: Marcio@destak.com.br | N38: 41996849234 | O38: 0 | P38: 0 | R38: Atendido | S38: 15015925662 | T38: =VLOOKUP(RANDBETWEEN(1,17),'Auxiliar Vendas'!D:G,2,0) -> Produto 16 | U38: 120 | V38: 4.99 | W38: 0 | X38: 3.74 | Y38: 598.8 | Z38: 41 | AA38: PRFL.00.0012 | AB38: 0 | AC38: 0 | AD38: HENRIQUE | AH38: 44438.383 | AI38: 0 | AJ38: 0 | AK38: =VLOOKUP(T38,'Auxiliar Vendas'!E:F,2,FALSE) -> Produto 16 | AL38: =U38*VLOOKUP(T38,'Auxiliar Vendas'!E:G,3,FALSE) -> 152.4
A39: 15279376352 | B39: 60 | D39: 44438 | E39: 15279322250 | F39: =VLOOKUP(RANDBETWEEN(1,20),'DBO Compras'!AA:AC,3,0) -> Comprador 15 | G39: 15.651.626/0001-35 | H39: RUA BRIGADEIRO FRANCO, 5024, LOJA 01 | I39: REBOUCAS | J39: Curitiba | K39: 80220100 | L39: PR | M39: Diego@Drywall.com.br | N39: 41993330017 | O39: 0 | P39: 0 | R39: Atendido | S39: 15015085610 | T39: =VLOOKUP(RANDBETWEEN(1,17),'Auxiliar Vendas'!D:G,2,0) -> Produto 07 | U39: 700 | V39: 13.9 | W39: 0 | X39: 10.23 | Y39: 9730 | Z39: 68 | AA39: PRFL.00.0001 | AB39: 0 | AC39: 0 | AH39: 44438.469 | AI39: 0 | AJ39: 0 | AK39: =VLOOKUP(T39,'Auxiliar Vendas'!E:F,2,FALSE) -> Produto 07 | AL39: =U39*VLOOKUP(T39,'Auxiliar Vendas'!E:G,3,FALSE) -> 770
A40: 15279376352 | B40: 60 | D40: 44438 | E40: 15279322250 | F40: =VLOOKUP(RANDBETWEEN(1,20),'DBO Compras'!AA:AC,3,0) -> Comprador 07 | G40: 15.651.626/0001-35 | H40: RUA BRIGADEIRO FRANCO, 5024, LOJA 01 | I40: REBOUCAS | J40: Curitiba | K40: 80220100 | L40: PR | M40: Diego@Drywall.com.br | N40: 41993330017 | O40: 0 | P40: 0 | R40: Atendido | S40: 15015353721 | T40: =VLOOKUP(RANDBETWEEN(1,17),'Auxiliar Vendas'!D:G,2,0) -> Produto 14 | U40: 700 | V40: 8.2 | W40: 0 | X40: 5.58 | Y40: 5740 | Z40: 68 | AA40: PRFL.00.0002 | AB40: 0 | AC40: 0 | AH40: 44438.469 | AI40: 0 | AJ40: 0 | AK40: =VLOOKUP(T40,'Auxiliar Vendas'!E:F,2,FALSE) -> Produto 14 | AL40: =U40*VLOOKUP(T40,'Auxiliar Vendas'!E:G,3,FALSE) -> 980
A41: 15279376352 | B41: 60 | D41: 44438 | E41: 15279322250 | F41: =VLOOKUP(RANDBETWEEN(1,20),'DBO Compras'!AA:AC,3,0) -> Comprador 09 | G41: 15.651.626/0001-35 | H41: RUA BRIGADEIRO FRANCO, 5024, LOJA 01 | I41: REBOUCAS | J41: Curitiba | K41: 80220100 | L41: PR | M41: Diego@Drywall.com.br | N41: 41993330017 | O41: 0 | P41: 0 | R41: Atendido | S41: 15015867005 | T41: =VLOOKUP(RANDBETWEEN(1,17),'Auxiliar Vendas'!D:G,2,0) -> Produto 12 | U41: 194 | V41: 18.2 | W41: 0 | X41: 13.764 | Y41: 3530.8 | Z41: 68 | AA41: PRFL.00.0008 | AB41: 0 | AC41: 0 | AH41: 44438.469 | AI41: 0 | AJ41: 0 | AK41: =VLOOKUP(T41,'Auxiliar Vendas'!E:F,2,FALSE) -> Produto 12 | AL41: =U41*VLOOKUP(T41,'Auxiliar Vendas'!E:G,3,FALSE) -> 271.6
A42: 15279376352 | B42: 60 | D42: 44438 | E42: 15279322250 | F42: =VLOOKUP(RANDBETWEEN(1,20),'DBO Compras'!AA:AC,3,0) -> Comprador 08 | G42: 15.651.626/0001-35 | H42: RUA BRIGADEIRO FRANCO, 5024, LOJA 01 | I42: REBOUCAS | J42: Curitiba | K42: 80220100 | L42: PR | M42: Diego@Drywall.com.br | N42: 41993330017 | O42: 0 | P42: 0 | R42: Atendido | S42: 15016093155 | T42: =VLOOKUP(RANDBETWEEN(1,17),'Auxiliar Vendas'!D:G,2,0) -> Produto 14 | U42: 6 | V42: 18.2 | W42: 0 | X42: 14.4596 | Y42: 109.2 | Z42: 68 | AA42: PRFL.00.0026 | AB42: 0 | AC42: 0 | AH42: 44438.469 | AI42: 0 | AJ42: 0 | AK42: =VLOOKUP(T42,'Auxiliar Vendas'!E:F,2,FALSE) -> Produto 14 | AL42: =U42*VLOOKUP(T42,'Auxiliar Vendas'!E:G,3,FALSE) -> 8.4
A43: 15293132741 | B43: 95 | D43: 44442 | E43: 15291803674 | F43: =VLOOKUP(RANDBETWEEN(1,20),'DBO Compras'!AA:AC,3,0) -> Comprador 10 | G43: 42.010.522/0001-14 | H43: RUA BLUMENAU, 101, GALPAO:01 | I43: centro | J43: Balneário Camboriú | K43: 88337440 | L43: SC | M43: Elizeu@Decorgesso.com.br | N43: 47996529345 | O43: 0 | P43: 0 | R43: Atendido | S43: 15016043939 | T43: =VLOOKUP(RANDBETWEEN(1,17),'Auxiliar Vendas'!D:G,2,0) -> Produto 16 | U43: 1000 | V43: 13.99 | W43: 0 | X43: 10.747 | Y43: 13990 | Z43: 73 | AA43: PRFL.00.0019 | AB43: 0 | AC43: 0 | AH43: 44442.578 | AI43: 0 | AJ43: 0 | AK43: =VLOOKUP(T43,'Auxiliar Vendas'!E:F,2,FALSE) -> Produto 16 | AL43: =U43*VLOOKUP(T43,'Auxiliar Vendas'!E:G,3,FALSE) -> 1270
A44: 15280230788 | B44: 65 | D44: 44466 | E44: 15179608501 | F44: =VLOOKUP(RANDBETWEEN(1,20),'DBO Compras'!AA:AC,3,0) -> Comprador 06 | G44: 25.195.001/0001-60 | H44: RUA ITACIANO MARCONDES, 47 | I44: SANTA CANDIDA | J44: Curitiba | K44: 82720070 | L44: PR | M44: Delta@Delta.com.br | N44: 41992354686 | O44: 0 | P44: 0 | R44: Atendido | S44: 15016099089 | T44: =VLOOKUP(RANDBETWEEN(1,17),'Auxiliar Vendas'!D:G,2,0) -> Produto 13 | U44: 200 | V44: 19.17 | W44: 0 | X44: 16.8044 | Y44: 3834 | Z44: 42 | AA44: PRFL.00.0027 | AB44: 0 | AC44: 0 | AH44: 44466.492 | AI44: 0 | AJ44: 0 | AK44: =VLOOKUP(T44,'Auxiliar Vendas'!E:F,2,FALSE) -> Produto 13 | AL44: =U44*VLOOKUP(T44,'Auxiliar Vendas'!E:G,3,FALSE) -> 280
A45: 15280230788 | B45: 65 | D45: 44466 | E45: 15179608501 | F45: =VLOOKUP(RANDBETWEEN(1,20),'DBO Compras'!AA:AC,3,0) -> Comprador 04 | G45: 25.195.001/0001-60 | H45: RUA ITACIANO MARCONDES, 47 | I45: SANTA CANDIDA | J45: Curitiba | K45: 82720070 | L45: PR | M45: Delta@Delta.com.br | N45: 41992354686 | O45: 0 | P45: 0 | R45: Atendido | S45: 15016099089 | T45: =VLOOKUP(RANDBETWEEN(1,17),'Auxiliar Vendas'!D:G,2,0) -> Produto 08 | U45: 200 | V45: 21.3 | W45: 0 | X45: 16.8044 | Y45: 4260 | Z45: 42 | AA45: PRFL.00.0027 | AB45: 0 | AC45: 0 | AH45: 44466.492 | AI45: 0 | AJ45: 0 | AK45: =VLOOKUP(T45,'Auxiliar Vendas'!E:F,2,FALSE) -> Produto 08 | AL45: =U45*VLOOKUP(T45,'Auxiliar Vendas'!E:G,3,FALSE) -> 220
A46: 15294739206 | B46: 102 | D46: 44468 | E46: 15179784707 | F46: =VLOOKUP(RANDBETWEEN(1,20),'DBO Compras'!AA:AC,3,0) -> Comprador 13 | G46: 18.552.908/0001-73 | H46: Rua Rio Tibagi, 787 | I46: Jardim Santo Amaro | J46: Cambé | K46: 86185130 | L46: PR | M46: amanda.hubbe@perfilar.ind.br | N46: 41996084664 | O46: 0 | P46: 0 | R46: Atendido | S46: 15015511068 | T46: =VLOOKUP(RANDBETWEEN(1,17),'Auxiliar Vendas'!D:G,2,0) -> Produto 05 | U46: 100 | V46: 16.7 | W46: 0 | X46: 10.23 | Y46: 1670 | Z46: 49 | AA46: PRFL.00.0005 | AB46: 0 | AC46: 0 | AH46: 44468.363 | AI46: 0 | AJ46: 0 | AK46: =VLOOKUP(T46,'Auxiliar Vendas'!E:F,2,FALSE) -> Produto 05 | AL46: =U46*VLOOKUP(T46,'Auxiliar Vendas'!E:G,3,FALSE) -> 60
A47: 15294739206 | B47: 102 | D47: 44468 | E47: 15179784707 | F47: =VLOOKUP(RANDBETWEEN(1,20),'DBO Compras'!AA:AC,3,0) -> Comprador 18 | G47: 18.552.908/0001-73 | H47: Rua Rio Tibagi, 787 | I47: Jardim Santo Amaro | J47: Cambé | K47: 86185130 | L47: PR | M47: amanda.hubbe@perfilar.ind.br | N47: 41996084664 | O47: 0 | P47: 0 | R47: Atendido | S47: 15016080333 | T47: =VLOOKUP(RANDBETWEEN(1,17),'Auxiliar Vendas'!D:G,2,0) -> Produto 08 | U47: 100 | V47: 15.5 | W47: 0 | X47: 10.747 | Y47: 1550 | Z47: 49 | AA47: PRFL.00.0024 | AB47: 0 | AC47: 0 | AH47: 44468.363 | AI47: 0 | AJ47: 0 | AK47: =VLOOKUP(T47,'Auxiliar Vendas'!E:F,2,FALSE) -> Produto 08 | AL47: =U47*VLOOKUP(T47,'Auxiliar Vendas'!E:G,3,FALSE) -> 110
...

Sheet Ven. Peso e Valor
A1: Soma Preço | B1: 378309
A2: Soma Peso | B2: =GETPIVOTDATA("Peso",$H$5) -> 330799.05
A3: Pç por Kg | B3: =B1/B2 -> 1.1436218
A5: Rótulos de Linha | B5: Soma de Peso | D5: Rótulos de Linha | E5: Soma de Preço Total | H5: Rótulos de Linha | I5: Soma de Peso
A6: Produto 17 | B6: 23253.92 | D6: Produto 10 | E6: 206733.6 | H6: Produto 14 | I6: 32229.4
A7: Produto 16 | B7: 28747.72 | D7: Produto 12 | E7: 264394 | H7: Produto 15 | I7: 30765.72
A8: Produto 15 | B8: 30765.72 | D8: Produto 05 | E8: 263275 | H8: Produto 12 | I8: 28851.2
A9: Produto 14 | B9: 32229.4 | D9: Produto 14 | E9: 296777.05 | H9: Produto 16 | I9: 28747.72
A10: Produto 13 | B10: 23472.4 | D10: Produto 01 | E10: 194362.7 | H10: Produto 07 | I10: 27149.1
A11: Produto 12 | B11: 28851.2 | D11: Produto 11 | E11: 310675.35 | H11: Produto 09 | I11: 24271.5
A12: Produto 11 | B12: 22511.5 | D12: Produto 07 | E12: 298308.42 | H12: Produto 13 | I12: 23472.4
A13: Produto 10 | B13: 17250.2 | D13: Produto 02 | E13: 284248.35 | H13: Produto 17 | I13: 23253.92
A14: Produto 09 | B14: 24271.5 | D14: Produto 13 | E14: 228561.95 | H14: Produto 11 | I14: 22511.5
A15: Produto 08 | B15: 20969.3 | D15: Produto 06 | E15: 284027.8 | H15: Produto 08 | I15: 20969.3
A16: Produto 07 | B16: 27149.1 | D16: Produto 16 | E16: 318759.62 | H16: Produto 10 | I16: 17250.2
A17: Produto 06 | B17: 10166.5 | D17: Produto 08 | E17: 237506.71 | H17: Produto 05 | I17: 12685.2
... A23: Total Geral | B23: 330799.05 | D23: Total Geral | E23: 4407761.3 | H23: Total Geral | I23: 330799.05

Sheet Ven. Mes
A1: Soma Preço | B1: =GETPIVOTDATA("Preço Total",$E$4) -> 4407761.3
A2: Soma Peso | B2: =GETPIVOTDATA("Soma de Peso",$A$4) -> 330799.05
A4: Rótulos de Linha | B4: Soma de Peso | E4: Rótulos de Linha | F4: Soma de Preço Total
A5: jul | B5: 8298.2 | E5: jul | F5: 78981.4
A6: ago | B6: 21089.1 | E6: ago | F6: 362769.02
A7: set | B7: 36989.82 | E7: set | F7: 495508.58
A8: out | B8: 62819.56 | E8: out | F8: 813769.1
A9: nov | B9: 93453.2 | E9: nov | F9: 1225974.5
A10: dez | B10: 108149.17 | E10: dez | F10: 1430758.7
A11: Total Geral | B11: 330799.05 | E11: Total Geral | F11: 4407761.3

Sheet TOP Compradores
A1: Posição | B1: Nome | C1: Vlr | E1: Rótulos de Linha | F1: Soma de Preço Total
A2: 1 | B2: =IF(OR(E2 = "Total Geral",E2 = ""),"N/A",E2) -> Comprador 13 | C2: =GETPIVOTDATA("Preço Total",$E$1,"Nome do contato",B2) -> 224562.5 | E2: Comprador 13 | F2: 224562.5
A3: 2 | B3: =IF(OR(E3 = "Total Geral",E3 = ""),"N/A",E3) -> Comprador 06 | C3: =GETPIVOTDATA("Preço Total",$E$1,"Nome do contato",B3) -> 228470.7 | E3: Comprador 06 | F3: 228470.7
A4: 3 | B4: =IF(OR(E4 = "Total Geral",E4 = ""),"N/A",E4) -> Comprador 10 | C4: =GETPIVOTDATA("Preço Total",$E$1,"Nome do contato",B4) -> 228833.32 | E4: Comprador 10 | F4: 228833.32
A5: 4 | B5: =IF(OR(E5 = "Total Geral",E5 = ""),"N/A",E5) -> Comprador 14 | C5: =GETPIVOTDATA("Preço Total",$E$1,"Nome do contato",B5) -> 241304.3 | E5: Comprador 14 | F5: 241304.3
A6: 5 | B6: =IF(OR(E6 = "Total Geral",E6 = ""),"N/A",E6) -> Comprador 20 | C6: =GETPIVOTDATA("Preço Total",$E$1,"Nome do contato",B6) -> 286837.3 | E6: Comprador 20 | F6: 286837.3
A7: 6 | B7: =IF(OR(E7 = "Total Geral",E7 = ""),"N/A",E7) -> Comprador 09 | C7: =GETPIVOTDATA("Preço Total",$E$1,"Nome do contato",B7) -> 320063.8 | E7: Comprador 09 | F7: 320063.8
A8: 7 | B8: =IF(OR(E8 = "Total Geral",E8 = ""),"N/A",E8) -> Comprador 16 | C8: =GETPIVOTDATA("Preço Total",$E$1,"Nome do contato",B8) -> 321532.82 | E8: Comprador 16 | F8: 321532.82
A9: 8 | B9: =IF(OR(E9 = "Total Geral",E9 = ""),"N/A",E9) -> Comprador 07 | C9: =GETPIVOTDATA("Preço Total",$E$1,"Nome do contato",B9) -> 349287.48 | E9: Comprador 07 | F9: 349287.48
A10: 9 | B10: =IF(OR(E10 = "Total Geral",E10 = ""),"N/A",E10) -> Comprador 08 | C10: =GETPIVOTDATA("Preço Total",$E$1,"Nome do contato",B10) -> 416624.35 | E10: Comprador 08 | F10: 416624.35
A11: 10 | B11: =IF(OR(E11 = "Total Geral",E11 = ""),"N/A",E11) -> Comprador 12 | C11: =GETPIVOTDATA("Preço Total",$E$1,"Nome do contato",B11) -> 450368.05 | E11: Comprador 12 | F11: 450368.05
E12: Total Geral | F12: 3067884.6

Sheet Auxiliar Vendas
B2: TABELA DE PESOS POR PEÇA
B4: PRODUTO | C4: PESO | E4: PRODUTO | F4: Prod. Resum | G4: PESO
B5: F530 | C5: 1.1 | D5: 1 | E5: Produto 01 | F5: Produto 01 | G5: 0.4 | I5: 1 | J5: ="Produto 0" &I5 -> Produto 01
B6: CANTONEIRA 25 X 30 | C6: 0.6 | D6: 2 | E6: Produto 02 | F6: Produto 02 | G6: 0.27 | I6: 2 | J6: ="Produto 0" &I6 -> Produto 02
B7: CANTONEIRA 15 X 20 | C7: 0.27 | D7: 3 | E7: Produto 03 | F7: Produto 03 | G7: 0.6 | I7: 3 | J7: ="Produto 0" &I7 -> Produto 03
B8: CANTONEIRA 23 X 23 PERF | C8: 0.5 | D8: 4 | E8: Produto 04 | F8: Produto 04 | G8: 0.6 | I8: 4 | J8: ="Produto 0" &I8 -> Produto 04
B9: GUIA 48 | C9: 1.1 | D9: 5 | E9: Produto 05 | F9: Produto 05 | G9: 0.6 | I9: 5 | J9: ="Produto 0" &I9 -> Produto 05
B10: GUIA 70 | C10: 1.4 | D10: 6 | E10: Produto 06 | F10: Produto 06 | G10: 0.5 | I10: 6 | J10: ="Produto 0" &I10 -> Produto 06
B11: GUIA 90 | C11: 1.62 | D11: 7 | E11: Produto 07 | F11: Produto 07 | G11: 1.1 | I11: 7 | J11: ="Produto 0" &I11 -> Produto 07
B12: MONTANTE 48 | C12: 1.42 | D12: 8 | E12: Produto 08 | F12: Produto 08 | G12: 1.1 | I12: 8 | J12: ="Produto 0" &I12 -> Produto 08
B13: MONTANTE 48 C/ 2,7 M | C13: 1.27 | D13: 9 | E13: Produto 09 | F13: Produto 09 | G13: 1.1 | I13: 9 | J13: ="Produto 0" &I13 -> Produto 09
B14: MONTANTE 70 | C14: 1.62 | D14: 10 | E14: Produto 10 | F14: Produto 10 | G14: 1.1 | I14: 10 | J14: ="Produto " &I14 -> Produto 10
B15: MONTANTE 90 | C15: 1.92 | D15: 11 | E15: Produto 11 | F15: Produto 11 | G15: 1.1 | I15: 11 | J15: ="Produto " &I15 -> Produto 11
B16: TABICA BRANCA | C16: 1.1 | D16: 12 | E16: Produto 12 | F16: Produto 12 | G16: 1.4 | I16: 12 | J16: ="Produto " &I16 -> Produto 12
B17: TABICA GALVANIZADA | C17: 1.1 | D17: 13 | E17: Produto 13 | F17: Produto 13 | G17: 1.4 | I17: 13 | J17: ="Produto " &I17 -> Produto 13
D18: 14 | E18: Produto 14 | F18: Produto 14 | G18: 1.4 | I18: 14 | J18: ="Produto " &I18 -> Produto 14
D19: 15 | E19: Produto 15 | F19: Produto 15 | G19: 1.42 | I19: 15 | J19: ="Produto " &I19 -> Produto 15
D20: 16 | E20: Produto 16 | F20: Produto 16 | G20: 1.27 | I20: 16 | J20: ="Produto " &I20 -> Produto 16
D21: 17 | E21: Produto 17 | F21: Produto 17 | G21: 1.42 | I21: 17 | J21: ="Produto " &I21 -> Produto 17
D22: 18 | E22: Produto 18 | F22: Produto 18 | G22: 1.18 | I22: 18 | J22: ="Produto " &I22 -> Produto 18
D23: 19 | E23: Produto 19 | F23: Produto 19 | G23: 1.32 | I23: 19 | J23: ="Produto " &I23 -> Produto 19
D24: 20 | E24: Produto 20 | F24: Produto 20 | G24: 1.62 | I24: 20 | J24: ="Produto " &I24 -> Produto 20
D25: 21 | E25: Produto 21 | F25: Produto 21 | G25: 1.62 | I25: 21 | J25: ="Produto " &I25 -> Produto 21
D26: 22 | E26: Produto 22 | F26: Produto 22 | G26: 2.53 | I26: 22 | J26: ="Produto " &I26 -> Produto 22
D27: 23 | E27: Produto 23 | F27: Produto 23 | G27: 1.94 | I27: 23 | J27: ="Produto " &I27 -> Produto 23
D28: 24 | E28: Produto 24 | F28: Produto 24 | G28: 2.75 | I28: 24 | J28: ="Produto " &I28 -> Produto 24
D29: 25 | E29: Produto 25 | F29: Produto 25 | G29: 0.6 | I29: 25 | J29: ="Produto " &I29 -> Produto 25
... D36: 32 | E36: Produto 32 | F36: Produto 32 | G36: 1.1 | I36: 32 | J36: ="Produto " &I36 -> Produto 32

Sheet DashBoard Compras

Sheet DBO Compras
A1: ID | B1: N° do pedido | C1: Data | D1: ID contato | E1: Nome do contato | F1: Desconto | G1: Observações | H1: Situação | I1: ID produto | J1: Código | K1: Código no fornecedor | L1: Descrição | M1: Quantidade | N1: Valor unitário | O1: Un | P1: Frete do item | Q1: Ordem de compra | R1: Descrição Resumida | S1: Imposto | T1: Peso | U1: Peso Total | V1: Vlr Total | W1: mês | X1: ano | AB1: produto | AC1: Fornecedor
A2: 15455633497 | B2: 1 | C2: 44533 | D2: 15139603329 | E2: =VLOOKUP(RANDBETWEEN(1,20),AA:AC,3,FALSE) -> Comprador 18 | F2: 0 | H2: Atendido | I2: 15016073255 | J2: PRFL.00.0023 | L2: =VLOOKUP(RANDBETWEEN(1,16),AA:AC,2,FALSE) -> Produto 05 | M2: 2520 | N2: 14.2 | O2: PC | P2: 0 | Q2: 4713 | R2: =VLOOKUP(L2,'Auxiliar Compras'!A:B,2,FALSE) -> Produto 05 | S2: =VLOOKUP(L2,'Auxiliar Compras'!A:D,4,FALSE) -> 0 | T2: =VLOOKUP(L2,'Auxiliar Compras'!A:C,3,FALSE) -> 1.42 | U2: =T2*M2 -> 3578.4 | V2: =N2*M2+(M2*N2*S2) -> 35784 | W2: =VLOOKUP(MONTH(Tabela2[[#This Row],[Data]]),'Auxiliar Compras'!I:J,2,FALSE) -> Dez | X2: =YEAR(Tabela2[[#This Row],[Data]]) -> 2021 | AA2: 1 | AB2: ="Produto 0" &AA2 -> Produto 01 | AC2: ="Comprador 0"&AA2 -> Comprador 01
A3: 15493600861 | B3: 3 | C3: 44537 | D3: 14772821922 | E3: =VLOOKUP(RANDBETWEEN(1,20),AA:AC,3,FALSE) -> Comprador 09 | F3: 0 | H3: Atendido | I3: 14980702561 | J3: ICHP.00.0006 | L3: =VLOOKUP(RANDBETWEEN(1,16),AA:AC,2,FALSE) -> Produto 04 | M3: 13359 | N3: 7.74 | O3: KG | P3: 0 | Q3: 4982 | R3: =VLOOKUP(L3,'Auxiliar Compras'!A:B,2,FALSE) -> Produto 04 | S3: =VLOOKUP(L3,'Auxiliar Compras'!A:D,4,FALSE) -> 0 | T3: =VLOOKUP(L3,'Auxiliar Compras'!A:C,3,FALSE) -> 1.1 | U3: =T3*M3 -> 14694.9 | V3: =N3*M3+(M3*N3*S3) -> 103398.66 | W3: =VLOOKUP(MONTH(Tabela2[[#This Row],[Data]]),'Auxiliar Compras'!I:J,2,FALSE) -> Dez | X3: =YEAR(Tabela2[[#This Row],[Data]]) -> 2021 | AA3: 2 | AB3: ="Produto 0" &AA3 -> Produto 02 | AC3: ="Comprador 0"&AA3 -> Comprador 02
A4: 15531010205 | B4: 4 | C4: 44540 | D4: 15139603329 | E4: =VLOOKUP(RANDBETWEEN(1,20),AA:AC,3,FALSE) -> Comprador 10 | F4: 0 | H4: Atendido | I4: 15016043939 | J4: PRFL.00.0019 | L4: =VLOOKUP(RANDBETWEEN(1,16),AA:AC,2,FALSE) -> Produto 13 | M4: 2520 | N4: 13.75 | O4: PC | P4: 0 | Q4: 5008 | R4: =VLOOKUP(L4,'Auxiliar Compras'!A:B,2,FALSE) -> Produto 13 | S4: =VLOOKUP(L4,'Auxiliar Compras'!A:D,4,FALSE) -> 0 | T4: =VLOOKUP(L4,'Auxiliar Compras'!A:C,3,FALSE) -> 0.4 | U4: =T4*M4 -> 1008 | V4: =N4*M4+(M4*N4*S4) -> 34650 | W4: =VLOOKUP(MONTH(Tabela2[[#This Row],[Data]]),'Auxiliar Compras'!I:J,2,FALSE) -> Dez | X4: =YEAR(Tabela2[[#This Row],[Data]]) -> 2021 | AA4: 3 | AB4: ="Produto 0" &AA4 -> Produto 03 | AC4: ="Comprador 0"&AA4 -> Comprador 03
A5: 15531010205 | B5: 4 | C5: 44540 | D5: 15139603329 | E5: =VLOOKUP(RANDBETWEEN(1,20),AA:AC,3,FALSE) -> Comprador 19 | F5: 0 | H5: Atendido | I5: 15016093155 | J5: PRFL.00.0026 | L5: =VLOOKUP(RANDBETWEEN(1,16),AA:AC,2,FALSE) -> Produto 13 | M5: 300 | N5: 21.1 | O5: PC | P5: 0 | Q5: 5008 | R5: =VLOOKUP(L5,'Auxiliar Compras'!A:B,2,FALSE) -> Produto 13 | S5: =VLOOKUP(L5,'Auxiliar Compras'!A:D,4,FALSE) -> 0 | T5: =VLOOKUP(L5,'Auxiliar Compras'!A:C,3,FALSE) -> 0.4 | U5: =T5*M5 -> 120 | V5: =N5*M5+(M5*N5*S5) -> 6330 | W5: =VLOOKUP(MONTH(Tabela2[[#This Row],[Data]]),'Auxiliar Compras'!I:J,2,FALSE) -> Dez | X5: =YEAR(Tabela2[[#This Row],[Data]]) -> 2021 | AA5: 4 | AB5: ="Produto 0" &AA5 -> Produto 04 | AC5: ="Comprador 0"&AA5 -> Comprador 04
A6: 15583785440 | B6: 5 | C6: 44540 | D6: 14772821922 | E6: =VLOOKUP(RANDBETWEEN(1,20),AA:AC,3,FALSE) -> Comprador 10 | F6: 0 | H6: Atendido | I6: 14980702561 | J6: ICHP.00.0006 | L6: =VLOOKUP(RANDBETWEEN(1,16),AA:AC,2,FALSE) -> Produto 01 | M6: 24620 | N6: 9.15 | O6: KG | P6: 0 | R6: =VLOOKUP(L6,'Auxiliar Compras'!A:B,2,FALSE) -> Produto 01 | S6: =VLOOKUP(L6,'Auxiliar Compras'!A:D,4,FALSE) -> 0 | T6: =VLOOKUP(L6,'Auxiliar Compras'!A:C,3,FALSE) -> 1.1 | U6: =T6*M6 -> 27082 | V6: =N6*M6+(M6*N6*S6) -> 225273 | W6: =VLOOKUP(MONTH(Tabela2[[#This Row],[Data]]),'Auxiliar Compras'!I:J,2,FALSE) -> Dez | X6: =YEAR(Tabela2[[#This Row],[Data]]) -> 2021 | AA6: 5 | AB6: ="Produto 0" &AA6 -> Produto 05 | AC6: ="Comprador 0"&AA6 -> Comprador 05
A7: 15634553057 | B7: 6 | C7: 44550 | D7: 15139603329 | E7: =VLOOKUP(RANDBETWEEN(1,20),AA:AC,3,FALSE) -> Comprador 10 | F7: 0 | H7: Atendido | I7: 15016073255 | J7: PRFL.00.0023 | L7: =VLOOKUP(RANDBETWEEN(1,16),AA:AC,2,FALSE) -> Produto 12 | M7: 2520 | N7: 13.9 | O7: PC | P7: 0 | Q7: 4955 | R7: =VLOOKUP(L7,'Auxiliar Compras'!A:B,2,FALSE) -> Produto 12 | S7: =VLOOKUP(L7,'Auxiliar Compras'!A:D,4,FALSE) -> 0 | T7: =VLOOKUP(L7,'Auxiliar Compras'!A:C,3,FALSE) -> 1 | U7: =T7*M7 -> 2520 | V7: =N7*M7+(M7*N7*S7) -> 35028 | W7: =VLOOKUP(MONTH(Tabela2[[#This Row],[Data]]),'Auxiliar Compras'!I:J,2,FALSE) -> Dez | X7: =YEAR(Tabela2[[#This Row],[Data]]) -> 2021 | AA7: 6 | AB7: ="Produto 0" &AA7 -> Produto 06 | AC7: ="Comprador 0"&AA7 -> Comprador 06
A8: 15634593361 | B8: 7 | C8: 44550 | D8: 15478914765 | E8: =VLOOKUP(RANDBETWEEN(1,20),AA:AC,3,FALSE) -> Comprador 17 | F8: 0 | H8: Atendido | I8: 15395751673 | J8: PRFL.00.0039 | L8: =VLOOKUP(RANDBETWEEN(1,16),AA:AC,2,FALSE) -> Produto 01 | M8: 700 | N8: 7.14 | O8: PC | P8: 0 | Q8: 5094 | R8: =VLOOKUP(L8,'Auxiliar Compras'!A:B,2,FALSE) -> Produto 01 | S8: =VLOOKUP(L8,'Auxiliar Compras'!A:D,4,FALSE) -> 0 | T8: =VLOOKUP(L8,'Auxiliar Compras'!A:C,3,FALSE) -> 1.1 | U8: =T8*M8 -> 770 | V8: =N8*M8+(M8*N8*S8) -> 4998 | W8: =VLOOKUP(MONTH(Tabela2[[#This Row],[Data]]),'Auxiliar Compras'!I:J,2,FALSE) -> Dez | X8: =YEAR(Tabela2[[#This Row],[Data]]) -> 2021 | AA8: 7 | AB8: ="Produto 0" &AA8 -> Produto 07 | AC8: ="Comprador 0"&AA8 -> Comprador 07
A9: 15634894365 | B9: 8 | C9: 44550 | D9: 15603445654 | E9: =VLOOKUP(RANDBETWEEN(1,20),AA:AC,3,FALSE) -> Comprador 15 | F9: 0 | H9: Atendido | I9: 14981306750 | J9: MTUC.00.0003 | L9: =VLOOKUP(RANDBETWEEN(1,16),AA:AC,2,FALSE) -> Produto 14 | M9: 2 | N9: 213.26 | O9: RL | P9: 0 | Q9: 5082 | R9: =VLOOKUP(L9,'Auxiliar Compras'!A:B,2,FALSE) -> Produto 14 | S9: =VLOOKUP(L9,'Auxiliar Compras'!A:D,4,FALSE) -> 0 | T9: =VLOOKUP(L9,'Auxiliar Compras'!A:C,3,FALSE) -> 1.68 | U9: =T9*M9 -> 3.36 | V9: =N9*M9+(M9*N9*S9) -> 426.52 | W9: =VLOOKUP(MONTH(Tabela2[[#This Row],[Data]]),'Auxiliar Compras'!I:J,2,FALSE) -> Dez | X9: =YEAR(Tabela2[[#This Row],[Data]]) -> 2021 | AA9: 8 | AB9: ="Produto 0" &AA9 -> Produto 08 | AC9: ="Comprador 0"&AA9 -> Comprador 08
A10: 15635001792 | B10: 9 | C10: 44550 | D10: 15603436233 | E10: =VLOOKUP(RANDBETWEEN(1,20),AA:AC,3,FALSE) -> Comprador 13 | F10: 0 | H10: Atendido | I10: 15634854583 | J10: SRV0.00.0012 | L10: =VLOOKUP(RANDBETWEEN(1,16),AA:AC,2,FALSE) -> Produto 14 | M10: 1 | N10: 1600 | P10: 0 | Q10: 5085 | R10: =VLOOKUP(L10,'Auxiliar Compras'!A:B,2,FALSE) -> Produto 14 | S10: =VLOOKUP(L10,'Auxiliar Compras'!A:D,4,FALSE) -> 0 | T10: =VLOOKUP(L10,'Auxiliar Compras'!A:C,3,FALSE) -> 1.68 | U10: =T10*M10 -> 1.68 | V10: =N10*M10+(M10*N10*S10) -> 1600 | W10: =VLOOKUP(MONTH(Tabela2[[#This Row],[Data]]),'Auxiliar Compras'!I:J,2,FALSE) -> Dez | X10: =YEAR(Tabela2[[#This Row],[Data]]) -> 2021 | AA10: 9 | AB10: ="Produto 0" &AA10 -> Produto 09 | AC10: ="Comprador 0"&AA10 -> Comprador 09
A11: 15635057711 | B11: 10 | C11: 44550 | D11: 15603436233 | E11: =VLOOKUP(RANDBETWEEN(1,20),AA:AC,3,FALSE) -> Comprador 06 | F11: 0 | H11: Atendido | I11: 15634854583 | J11: SRV0.00.0012 | L11: =VLOOKUP(RANDBETWEEN(1,16),AA:AC,2,FALSE) -> Produto 05 | M11: 2 | N11: 1950 | P11: 0 | Q11: 5085 | R11: =VLOOKUP(L11,'Auxiliar Compras'!A:B,2,FALSE) -> Produto 05 | S11: =VLOOKUP(L11,'Auxiliar Compras'!A:D,4,FALSE) -> 0 | T11: =VLOOKUP(L11,'Auxiliar Compras'!A:C,3,FALSE) -> 1.42 | U11: =T11*M11 -> 2.84 | V11: =N11*M11+(M11*N11*S11) -> 3900 | W11: =VLOOKUP(MONTH(Tabela2[[#This Row],[Data]]),'Auxiliar Compras'!I:J,2,FALSE) -> Dez | X11: =YEAR(Tabela2[[#This Row],[Data]]) -> 2021 | AA11: 10 | AB11: ="Produto " &AA11 -> Produto 10 | AC11: ="Comprador "&AA11 -> Comprador 10
A12: 15656137428 | B12: 11 | C12: 44552 | D12: 15130445011 | E12: =VLOOKUP(RANDBETWEEN(1,20),AA:AC,3,FALSE) -> Comprador 06 | F12: 0 | H12: Atendido | I12: 14981313809 | J12: ICHP.00.0001 | L12: =VLOOKUP(RANDBETWEEN(1,16),AA:AC,2,FALSE) -> Produto 04 | M12: 20402 | N12: 9.2 | O12: KG | P12: 0 | R12: =VLOOKUP(L12,'Auxiliar Compras'!A:B,2,FALSE) -> Produto 04 | S12: =VLOOKUP(L12,'Auxiliar Compras'!A:D,4,FALSE) -> 0 | T12: =VLOOKUP(L12,'Auxiliar Compras'!A:C,3,FALSE) -> 1.1 | U12: =T12*M12 -> 22442.2 | V12: =N12*M12+(M12*N12*S12) -> 187698.4 | W12: =VLOOKUP(MONTH(Tabela2[[#This Row],[Data]]),'Auxiliar Compras'!I:J,2,FALSE) -> Dez | X12: =YEAR(Tabela2[[#This Row],[Data]]) -> 2021 | AA12: 11 | AB12: ="Produto " &AA12 -> Produto 11 | AC12: ="Comprador "&AA12 -> Comprador 11
A13: 15656216577 | B13: 12 | C13: 44552 | D13: 15139603329 | E13: =VLOOKUP(RANDBETWEEN(1,20),AA:AC,3,FALSE) -> Comprador 18 | F13: 0 | H13: Atendido | I13: 15016073255 | J13: PRFL.00.0023 | L13: =VLOOKUP(RANDBETWEEN(1,16),AA:AC,2,FALSE) -> Produto 08 | M13: 4620 | N13: 13.9 | O13: PC | P13: 0 | Q13: 5095 | R13: =VLOOKUP(L13,'Auxiliar Compras'!A:B,2,FALSE) -> Produto 08 | S13: =VLOOKUP(L13,'Auxiliar Compras'!A:D,4,FALSE) -> 0 | T13: =VLOOKUP(L13,'Auxiliar Compras'!A:C,3,FALSE) -> 1 | U13: =T13*M13 -> 4620 | V13: =N13*M13+(M13*N13*S13) -> 64218 | W13: =VLOOKUP(MONTH(Tabela2[[#This Row],[Data]]),'Auxiliar Compras'!I:J,2,FALSE) -> Dez | X13: =YEAR(Tabela2[[#This Row],[Data]]) -> 2021 | AA13: 12 | AB13: ="Produto " &AA13 -> Produto 12 | AC13: ="Comprador "&AA13 -> Comprador 12
A14: 15656216577 | B14: 12 | C14: 44552 | D14: 15139603329 | E14: =VLOOKUP(RANDBETWEEN(1,20),AA:AC,3,FALSE) -> Comprador 05 | F14: 0 | H14: Atendido | I14: 15016093155 | J14: PRFL.00.0026 | L14: =VLOOKUP(RANDBETWEEN(1,16),AA:AC,2,FALSE) -> Produto 02 | M14: 900 | N14: 21.1 | O14: PC | P14: 0 | Q14: 5095 | R14: =VLOOKUP(L14,'Auxiliar Compras'!A:B,2,FALSE) -> Produto 02 | S14: =VLOOKUP(L14,'Auxiliar Compras'!A:D,4,FALSE) -> 0.05 | T14: =VLOOKUP(L14,'Auxiliar Compras'!A:C,3,FALSE) -> 1 | U14: =T14*M14 -> 900 | V14: =N14*M14+(M14*N14*S14) -> 19939.5 | W14: =VLOOKUP(MONTH(Tabela2[[#This Row],[Data]]),'Auxiliar Compras'!I:J,2,FALSE) -> Dez | X14: =YEAR(Tabela2[[#This Row],[Data]]) -> 2021 | AA14: 13 | AB14: ="Produto " &AA14 -> Produto 13 | AC14: ="Comprador "&AA14 -> Comprador 13
A15: 15656379350 | B15: 13 | C15: 44552 | D15: 15018323304 | E15: =VLOOKUP(RANDBETWEEN(1,20),AA:AC,3,FALSE) -> Comprador 13 | F15: 0 | H15: Atendido | I15: 14981313809 | J15: ICHP.00.0001 | L15: =VLOOKUP(RANDBETWEEN(1,16),AA:AC,2,FALSE) -> Produto 05 | M15: 25497 | N15: 9.38 | O15: KG | P15: 0 | R15: =VLOOKUP(L15,'Auxiliar Compras'!A:B,2,FALSE) -> Produto 05 | S15: =VLOOKUP(L15,'Auxiliar Compras'!A:D,4,FALSE) -> 0 | T15: =VLOOKUP(L15,'Auxiliar Compras'!A:C,3,FALSE) -> 1.42 | U15: =T15*M15 -> 36205.74 | V15: =N15*M15+(M15*N15*S15) -> 239161.86 | W15: =VLOOKUP(MONTH(Tabela2[[#This Row],[Data]]),'Auxiliar Compras'!I:J,2,FALSE) -> Dez | X15: =YEAR(Tabela2[[#This Row],[Data]]) -> 2021 | AA15: 14 | AB15: ="Produto " &AA15 -> Produto 14 | AC15: ="Comprador "&AA15 -> Comprador 14
A16: 15656392237 | B16: 14 | C16: 44552 | D16: 15018323304 | E16: =VLOOKUP(RANDBETWEEN(1,20),AA:AC,3,FALSE) -> Comprador 11 | F16: 0 | H16: Atendido | I16: 14981313809 | J16: ICHP.00.0001 | L16: =VLOOKUP(RANDBETWEEN(1,16),AA:AC,2,FALSE) -> Produto 09 | M16: 7100 | N16: 9.65 | O16: KG | P16: 0 | R16: =VLOOKUP(L16,'Auxiliar Compras'!A:B,2,FALSE) -> Produto 09 | S16: =VLOOKUP(L16,'Auxiliar Compras'!A:D,4,FALSE) -> 0 | T16: =VLOOKUP(L16,'Auxiliar Compras'!A:C,3,FALSE) -> 1 | U16: =T16*M16 -> 7100 | V16: =N16*M16+(M16*N16*S16) -> 68515 | W16: =VLOOKUP(MONTH(Tabela2[[#This Row],[Data]]),'Auxiliar Compras'!I:J,2,FALSE) -> Dez | X16: =YEAR(Tabela2[[#This Row],[Data]]) -> 2021 | AA16: 15 | AB16: ="Produto " &AA16 -> Produto 15 | AC16: ="Comprador "&AA16 -> Comprador 15
A17: 15656403917 | B17: 15 | C17: 44552 | D17: 15018323304 | E17: =VLOOKUP(RANDBETWEEN(1,20),AA:AC,3,FALSE) -> Comprador 03 | F17: 0 | H17: Atendido | I17: 14981313809 | J17: ICHP.00.0001 | L17: =VLOOKUP(RANDBETWEEN(1,16),AA:AC,2,FALSE) -> Produto 07 | M17: 7510 | N17: 9.35 | O17: KG | P17: 0 | R17: =VLOOKUP(L17,'Auxiliar Compras'!A:B,2,FALSE) -> Produto 07 | S17: =VLOOKUP(L17,'Auxiliar Compras'!A:D,4,FALSE) -> 0 | T17: =VLOOKUP(L17,'Auxiliar Compras'!A:C,3,FALSE) -> 0.5 | U17: =T17*M17 -> 3755 | V17: =N17*M17+(M17*N17*S17) -> 70218.5 | W17: =VLOOKUP(MONTH(Tabela2[[#This Row],[Data]]),'Auxiliar Compras'!I:J,2,FALSE) -> Dez | X17: =YEAR(Tabela2[[#This Row],[Data]]) -> 2021 | AA17: 16 | AB17: ="Produto " &AA17 -> Produto 16 | AC17: ="Comprador "&AA17 -> Comprador 16
A18: 15656417923 | B18: 16 | C18: 44552 | D18: 15018323304 | E18: =VLOOKUP(RANDBETWEEN(1,20),AA:AC,3,FALSE) -> Comprador 02 | F18: 0 | H18: Atendido | I18: 14981313809 | J18: ICHP.00.0001 | L18: =VLOOKUP(RANDBETWEEN(1,16),AA:AC,2,FALSE) -> Produto 02 | M18: 23476 | N18: 9.48 | O18: KG | P18: 0 | R18: =VLOOKUP(L18,'Auxiliar Compras'!A:B,2,FALSE) -> Produto 02 | S18: =VLOOKUP(L18,'Auxiliar Compras'!A:D,4,FALSE) -> 0.05 | T18: =VLOOKUP(L18,'Auxiliar Compras'!A:C,3,FALSE) -> 1 | U18: =T18*M18 -> 23476 | V18: =N18*M18+(M18*N18*S18) -> 233680.1 | W18: =VLOOKUP(MONTH(Tabela2[[#This Row],[Data]]),'Auxiliar Compras'!I:J,2,FALSE) -> Dez | X18: =YEAR(Tabela2[[#This Row],[Data]]) -> 2021 | AA18: 17 | AC18: ="Comprador "&AA18 -> Comprador 17
A19: 15656431575 | B19: 17 | C19: 44552 | D19: 15018323304 | E19: =VLOOKUP(RANDBETWEEN(1,20),AA:AC,3,FALSE) -> Comprador 20 | F19: 0 | H19: Atendido | I19: 14981313809 | J19: ICHP.00.0001 | L19: =VLOOKUP(RANDBETWEEN(1,16),AA:AC,2,FALSE) -> Produto 09 | M19: 26808 | N19: 9.2 | O19: KG | P19: 0 | R19: =VLOOKUP(L19,'Auxiliar Compras'!A:B,2,FALSE) -> Produto 09 | S19: =VLOOKUP(L19,'Auxiliar Compras'!A:D,4,FALSE) -> 0 | T19: =VLOOKUP(L19,'Auxiliar Compras'!A:C,3,FALSE) -> 1 | U19: =T19*M19 -> 26808 | V19: =N19*M19+(M19*N19*S19) -> 246633.6 | W19: =VLOOKUP(MONTH(Tabela2[[#This Row],[Data]]),'Auxiliar Compras'!I:J,2,FALSE) -> Dez | X19: =YEAR(Tabela2[[#This Row],[Data]]) -> 2021 | AA19: 18 | AC19: ="Comprador "&AA19 -> Comprador 18
A20: 15656455702 | B20: 18 | C20: 44552 | D20: 15478914765 | E20: =VLOOKUP(RANDBETWEEN(1,20),AA:AC,3,FALSE) -> Comprador 07 | F20: 0 | H20: Atendido | I20: 15395751673 | J20: PRFL.00.0039 | L20: =VLOOKUP(RANDBETWEEN(1,16),AA:AC,2,FALSE) -> Produto 11 | M20: 1700 | N20: 7.14 | O20: PC | P20: 0 | Q20: 5094 | R20: =VLOOKUP(L20,'Auxiliar Compras'!A:B,2,FALSE) -> Produto 11 | S20: =VLOOKUP(L20,'Auxiliar Compras'!A:D,4,FALSE) -> 0 | T20: =VLOOKUP(L20,'Auxiliar Compras'!A:C,3,FALSE) -> 1 | U20: =T20*M20 -> 1700 | V20: =N20*M20+(M20*N20*S20) -> 12138 | W20: =VLOOKUP(MONTH(Tabela2[[#This Row],[Data]]),'Auxiliar Compras'!I:J,2,FALSE) -> Dez | X20: =YEAR(Tabela2[[#This Row],[Data]]) -> 2021 | AA20: 19 | AC20: ="Comprador "&AA20 -> Comprador 19
A21: 15656725936 | B21: 19 | C21: 44552 | D21: 14772821922 | E21: =VLOOKUP(RANDBETWEEN(1,20),AA:AC,3,FALSE) -> Comprador 10 | F21: 0 | H21: Atendido | I21: 14980702561 | J21: ICHP.00.0006 | L21: =VLOOKUP(RANDBETWEEN(1,16),AA:AC,2,FALSE) -> Produto 02 | M21: 23968 | N21: 9.77 | O21: KG | P21: 0 | Q21: 3646 | R21: =VLOOKUP(L21,'Auxiliar Compras'!A:B,2,FALSE) -> Produto 02 | S21: =VLOOKUP(L21,'Auxiliar Compras'!A:D,4,FALSE) -> 0.05 | T21: =VLOOKUP(L21,'Auxiliar Compras'!A:C,3,FALSE) -> 1 | U21: =T21*M21 -> 23968 | V21: =N21*M21+(M21*N21*S21) -> 245875.73 | W21: =VLOOKUP(MONTH(Tabela2[[#This Row],[Data]]),'Auxiliar Compras'!I:J,2,FALSE) -> Dez | X21: =YEAR(Tabela2[[#This Row],[Data]]) -> 2021 | AA21: 20 | AC21: ="Comprador "&AA21 -> Comprador 20
A22: 15656740402 | B22: 20 | C22: 44552 | D22: 14772821922 | E22: =VLOOKUP(RANDBETWEEN(1,20),AA:AC,3,FALSE) -> Comprador 08 | F22: 0 | H22: Atendido | I22: 14980702561 | J22: ICHP.00.0006 | L22: =VLOOKUP(RANDBETWEEN(1,16),AA:AC,2,FALSE) -> Produto 05 | M22: 13440 | N22: 9.3 | O22: KG | P22: 0 | Q22: 3977 | R22: =VLOOKUP(L22,'Auxiliar Compras'!A:B,2,FALSE) -> Produto 05 | S22: =VLOOKUP(L22,'Auxiliar Compras'!A:D,4,FALSE) -> 0 | T22: =VLOOKUP(L22,'Auxiliar Compras'!A:C,3,FALSE) -> 1.42 | U22: =T22*M22 -> 19084.8 | V22: =N22*M22+(M22*N22*S22) -> 124992 | W22: =VLOOKUP(MONTH(Tabela2[[#This Row],[Data]]),'Auxiliar Compras'!I:J,2,FALSE) -> Dez | X22: =YEAR(Tabela2[[#This Row],[Data]]) -> 2021
A23: 15656778040 | B23: 21 | C23: 44552 | D23: 14772821922 | E23: =VLOOKUP(RANDBETWEEN(1,20),AA:AC,3,FALSE) -> Comprador 16 | F23: 0 | H23: Atendido | I23: 14980702561 | J23: ICHP.00.0006 | L23: =VLOOKUP(RANDBETWEEN(1,16),AA:AC,2,FALSE) -> Produto 13 | M23: 11818 | N23: 9.3 | O23: KG | P23: 0 | Q23: 4013 | R23: =VLOOKUP(L23,'Auxiliar Compras'!A:B,2,FALSE) -> Produto 13 | S23: =VLOOKUP(L23,'Auxiliar Compras'!A:D,4,FALSE) -> 0 | T23: =VLOOKUP(L23,'Auxiliar Compras'!A:C,3,FALSE) -> 0.4 | U23: =T23*M23 -> 4727.2 | V23: =N23*M23+(M23*N23*S23) -> 109907.4 | W23: =VLOOKUP(MONTH(Tabela2[[#This Row],[Data]]),'Auxiliar Compras'!I:J,2,FALSE) -> Dez | X23: =YEAR(Tabela2[[#This Row],[Data]]) -> 2021
A24: 15656795929 | B24: 22 | C24: 44552 | D24: 14772821922 | E24: =VLOOKUP(RANDBETWEEN(1,20),AA:AC,3,FALSE) -> Comprador 07 | F24: 0 | H24: Atendido | I24: 14980702561 | J24: ICHP.00.0006 | L24: =VLOOKUP(RANDBETWEEN(1,16),AA:AC,2,FALSE) -> Produto 15 | M24: 8588 | N24: 9.3 | O24: KG | P24: 0 | Q24: 4118 | R24: =VLOOKUP(L24,'Auxiliar Compras'!A:B,2,FALSE) -> Produto 15 | S24: =VLOOKUP(L24,'Auxiliar Compras'!A:D,4,FALSE) -> 0 | T24: =VLOOKUP(L24,'Auxiliar Compras'!A:C,3,FALSE) -> 1.1 | U24: =T24*M24 -> 9446.8 | V24: =N24*M24+(M24*N24*S24) -> 79868.4 | W24: =VLOOKUP(MONTH(Tabela2[[#This Row],[Data]]),'Auxiliar Compras'!I:J,2,FALSE) -> Dez | X24: =YEAR(Tabela2[[#This Row],[Data]]) -> 2021
A25: 15656813379 | B25: 23 | C25: 44552 | D25: 14772821922 | E25: =VLOOKUP(RANDBETWEEN(1,20),AA:AC,3,FALSE) -> Comprador 20 | F25: 0 | H25: Atendido | I25: 14980702561 | J25: ICHP.00.0006 | L25: =VLOOKUP(RANDBETWEEN(1,16),AA:AC,2,FALSE) -> Produto 06 | M25: 14106 | N25: 7.93 | O25: KG | P25: 0 | Q25: 4606 | R25: =VLOOKUP(L25,'Auxiliar Compras'!A:B,2,FALSE) -> Produto 06 | S25: =VLOOKUP(L25,'Auxiliar Compras'!A:D,4,FALSE) -> 0 | T25: =VLOOKUP(L25,'Auxiliar Compras'!A:C,3,FALSE) -> 1.1 | U25: =T25*M25 -> 15516.6 | V25: =N25*M25+(M25*N25*S25) -> 111860.58 | W25: =VLOOKUP(MONTH(Tabela2[[#This Row],[Data]]),'Auxiliar Compras'!I:J,2,FALSE) -> Dez | X25: =YEAR(Tabela2[[#This Row],[Data]]) -> 2021
A26: 15656822711 | B26: 24 | C26: 44552 | D26: 14772821922 | E26: =VLOOKUP(RANDBETWEEN(1,20),AA:AC,3,FALSE) -> Comprador 14 | F26: 0 | H26: Atendido | I26: 14980702561 | J26: ICHP.00.0006 | L26: =VLOOKUP(RANDBETWEEN(1,16),AA:AC,2,FALSE) -> Produto 08 | M26: 27695 | N26: 8.98 | O26: KG | P26: 0 | Q26: 4606 | R26: =VLOOKUP(L26,'Auxiliar Compras'!A:B,2,FALSE) -> Produto 08 | S26: =VLOOKUP(L26,'Auxiliar Compras'!A:D,4,FALSE) -> 0 | T26: =VLOOKUP(L26,'Auxiliar Compras'!A:C,3,FALSE) -> 1 | U26: =T26*M26 -> 27695 | V26: =N26*M26+(M26*N26*S26) -> 248701.1 | W26: =VLOOKUP(MONTH(Tabela2[[#This Row],[Data]]),'Auxiliar Compras'!I:J,2,FALSE) -> Dez | X26: =YEAR(Tabela2[[#This Row],[Data]]) -> 2021
A27: 15656842731 | B27: 25 | C27: 44552 | D27: 14772821922 | E27: =VLOOKUP(RANDBETWEEN(1,20),AA:AC,3,FALSE) -> Comprador 06 | F27: 0 | H27: Atendido | I27: 14980702561 | J27: ICHP.00.0006 | L27: =VLOOKUP(RANDBETWEEN(1,16),AA:AC,2,FALSE) -> Produto 09 | M27: 25188 | N27: 9.5 | O27: KG | P27: 0 | Q27: 4730 | R27: =VLOOKUP(L27,'Auxiliar Compras'!A:B,2,FALSE) -> Produto 09 | S27: =VLOOKUP(L27,'Auxiliar Compras'!A:D,4,FALSE) -> 0 | T27: =VLOOKUP(L27,'Auxiliar Compras'!A:C,3,FALSE) -> 1 | U27: =T27*M27 -> 25188 | V27: =N27*M27+(M27*N27*S27) -> 239286 | W27: =VLOOKUP(MONTH(Tabela2[[#This Row],[Data]]),'Auxiliar Compras'!I:J,2,FALSE) -> Dez | X27: =YEAR(Tabela2[[#This Row],[Data]]) -> 2021
A28: 15656853363 | B28: 26 | C28: 44552 | D28: 14772821922 | E28: =VLOOKUP(RANDBETWEEN(1,20),AA:AC,3,FALSE) -> Comprador 11 | F28: 0 | H28: Atendido | I28: 14980702561 | J28: ICHP.00.0006 | L28: =VLOOKUP(RANDBETWEEN(1,16),AA:AC,2,FALSE) -> Produto 16 | M28: 25043 | N28: 9.4 | O28: KG | P28: 0 | Q28: 4748 | R28: =VLOOKUP(L28,'Auxiliar Compras'!A:B,2,FALSE) -> Produto 16 | S28: =VLOOKUP(L28,'Auxiliar Compras'!A:D,4,FALSE) -> 0.05 | T28: =VLOOKUP(L28,'Auxiliar Compras'!A:C,3,FALSE) -> 1 | U28: =T28*M28 -> 25043 | V28: =N28*M28+(M28*N28*S28) -> 247174.41 | W28: =VLOOKUP(MONTH(Tabela2[[#This Row],[Data]]),'Auxiliar Compras'!I:J,2,FALSE) -> Dez | X28: =YEAR(Tabela2[[#This Row],[Data]]) -> 2021
A29: 15656876602 | B29: 27 | C29: 44552 | D29: 15450924520 | E29: =VLOOKUP(RANDBETWEEN(1,20),AA:AC,3,FALSE) -> Comprador 19 | F29: 0 | H29: Atendido | I29: 14980702561 | J29: ICHP.00.0006 | L29: =VLOOKUP(RANDBETWEEN(1,16),AA:AC,2,FALSE) -> Produto 02 | M29: 22885 | N29: 8.75 | O29: KG | P29: 0 | Q29: 4842 | R29: =VLOOKUP(L29,'Auxiliar Compras'!A:B,2,FALSE) -> Produto 02 | S29: =VLOOKUP(L29,'Auxiliar Compras'!A:D,4,FALSE) -> 0.05 | T29: =VLOOKUP(L29,'Auxiliar Compras'!A:C,3,FALSE) -> 1 | U29: =T29*M29 -> 22885 | V29: =N29*M29+(M29*N29*S29) -> 210255.94 | W29: =VLOOKUP(MONTH(Tabela2[[#This Row],[Data]]),'Auxiliar Compras'!I:J,2,FALSE) -> Dez | X29: =YEAR(Tabela2[[#This Row],[Data]]) -> 2021
A30: 15657069663 | B30: 28 | C30: 44552 | D30: 14979221560 | E30: =VLOOKUP(RANDBETWEEN(1,20),AA:AC,3,FALSE) -> Comprador 08 | F30: 0 | H30: Atendido | I30: 14979354095 | J30: INDS.00.0001 | K30: 50790031 | L30: =VLOOKUP(RANDBETWEEN(1,16),AA:AC,2,FALSE) -> Produto 07 | M30: 23968 | N30: 0.18 | O30: TO | P30: 0 | Q30: 3682 | R30: =VLOOKUP(L30,'Auxiliar Compras'!A:B,2,FALSE) -> Produto 07 | S30: =VLOOKUP(L30,'Auxiliar Compras'!A:D,4,FALSE) -> 0 | T30: =VLOOKUP(L30,'Auxiliar Compras'!A:C,3,FALSE) -> 0.5 | U30: =T30*M30 -> 11984 | V30: =N30*M30+(M30*N30*S30) -> 4314.24 | W30: =VLOOKUP(MONTH(Tabela2[[#This Row],[Data]]),'Auxiliar Compras'!I:J,2,FALSE) -> Dez | X30: =YEAR(Tabela2[[#This Row],[Data]]) -> 2021
A31: 15657078733 | B31: 29 | C31: 44552 | D31: 14979221560 | E31: =VLOOKUP(RANDBETWEEN(1,20),AA:AC,3,FALSE) -> Comprador 02 | F31: 0 | H31: Atendido | I31: 14979354095 | J31: INDS.00.0001 | K31: 50790031 | L31: =VLOOKUP(RANDBETWEEN(1,16),AA:AC,2,FALSE) -> Produto 10 | M31: 30773 | N31: 0.18 | O31: TO | P31: 0 | Q31: 3983/4041/4132 | R31: =VLOOKUP(L31,'Auxiliar Compras'!A:B,2,FALSE) -> Produto 10 | S31: =VLOOKUP(L31,'Auxiliar Compras'!A:D,4,FALSE) -> 0 | T31: =VLOOKUP(L31,'Auxiliar Compras'!A:C,3,FALSE) -> 1 | U31: =T31*M31 -> 30773 | V31: =N31*M31+(M31*N31*S31) -> 5539.14 | W31: =VLOOKUP(MONTH(Tabela2[[#This Row],[Data]]),'Auxiliar Compras'!I:J,2,FALSE) -> Dez | X31: =YEAR(Tabela2[[#This Row],[Data]]) -> 2021
A32: 15657087809 | B32: 30 | C32: 44552 | D32: 14979221560 | E32: =VLOOKUP(RANDBETWEEN(1,20),AA:AC,3,FALSE) -> Comprador 02 | F32: 0 | H32: Atendido | I32: 14979354095 | J32: INDS.00.0001 | K32: 50790031 | L32: =VLOOKUP(RANDBETWEEN(1,16),AA:AC,2,FALSE) -> Produto 02 | M32: 42704 | N32: 0.18 | O32: TO | P32: 0 | Q32: 4235/4287/4348 | R32: =VLOOKUP(L32,'Auxiliar Compras'!A:B,2,FALSE) -> Produto 02 | S32: =VLOOKUP(L32,'Auxiliar Compras'!A:D,4,FALSE) -> 0.05 | T32: =VLOOKUP(L32,'Auxiliar Compras'!A:C,3,FALSE) -> 1 | U32: =T32*M32 -> 42704 | V32: =N32*M32+(M32*N32*S32) -> 8071.056 | W32: =VLOOKUP(MONTH(Tabela2[[#This Row],[Data]]),'Auxiliar Compras'!I:J,2,FALSE) -> Dez | X32: =YEAR(Tabela2[[#This Row],[Data]]) -> 2021
